Workbook

Sheet 01_Dashboard
A1: VALGAVOTH — HARROWER OF SOULS | SLUG • VOLTRON • DEMONS
A3: Metric | B3: Current | D3: DECK IDENTITY
A4: Deck size | B4: =SUM('02_Card Matrix'!B2:B84) -> 99 | D4: Primary Plan — Voltron Valgavoth: grow +1/+1 counters from opponent-turn life loss and win with 21 commander damage.
A5: Land count | B5: =SUMIF('02_Card Matrix'!T2:T84,"YES",'02_Card Matrix'!B2:B84) -> 32 | D5: Secondary Plan — Group Slug: make opponents lose life on their turns to generate cards + counters.
A6: Current score | B6: =SUMPRODUCT('02_Card Matrix'!B2:B84,'02_Card Matrix'!N2:N84)/SUM('02_Card Matrix'!B2:B84) -> 8.2010101 | D6: Subtheme — Demon Tribal: Demons provide flavor, tutors, cost reduction and board-control payoffs.
A7: Demon cards | B7: =SUMIF('02_Card Matrix'!E2:E84,"YES",'02_Card Matrix'!B2:B84) -> 10 | D7: Resilience — Protect Valgavoth and preserve accumulated counters; prioritize cheap/free protection and counter preservation.
A8: S-tier cards | B8: =COUNTIF('02_Card Matrix'!O2:O84,"S") -> 8 | D8: Removal Philosophy — Prefer one-sided or commander-centric clears; Mandate of Abaddon and Chandra's Ignition are premium.
A9: A-tier cards | B9: =COUNTIF('02_Card Matrix'!O2:O84,"A") -> 33 | D9: Speed Philosophy — Keep lands; reduce unnecessary 6–8 MV spells and establish Valgavoth early.
A10: List status | B10: 99 cards listed — 1 slot is missing from supplied list | D10: 10/10 Rule — A non-Demon must materially improve speed, Voltron, life-loss triggers, protection, removal or Demon tribal to earn a slot.
A13: Tier | B13: Count
A14: S | B14: =COUNTIF('02_Card Matrix'!O2:O84,"S") -> 8
A15: A | B15: =COUNTIF('02_Card Matrix'!O2:O84,"A") -> 33
A16: B | B16: =COUNTIF('02_Card Matrix'!O2:O84,"B") -> 26
A17: C | B17: =COUNTIF('02_Card Matrix'!O2:O84,"C") -> 12

Sheet 02_Card Matrix
A1: Card | B1: Qty | C1: Type | D1: MV | E1: Demon? | F1: Ramp | G1: Draw | H1: Removal | I1: Protection | J1: Voltron | K1: Group Slug | L1: Recursion | M1: Demon Tribal | N1: Score | O1: Tier | P1: Verdict | Q1: Weakness | R1: Diagnosis | S1: Source | T1: Land?
A2: Valgavoth, Harrower of Souls | B2: 1 | C2: Legendary Creature — Elder Demon | D2: 4 | E2: YES | F2: 0 | G2: 1 | H2: 0 | I2: 2 | J2: 2 | K2: 2 | L2: 0 | M2: 2 | N2: 10 | O2: S | P2: LOCK | R2: Primary engine and Voltron threat. Each opponent's first life loss on their turn becomes a card plus a permanent +1/+1 counter. | S2: https://scryfall.com/search?q=%21%22Valgavoth%2C%20Harrower%20of%20Souls%22 | T2: NO
A3: Arcane Signet | B3: 1 | C3: Artifact | D3: 2 | E3: NO | F3: 2 | G3: 0 | H3: 0 | I3: 0 | J3: 0 | K3: 0 | L3: 0 | M3: 0 | N3: 7.5 | O3: B | P3: KEEP | R3: Strong support card for the deck's overall plan. | S3: https://scryfall.com/search?q=%21%22Arcane%20Signet%22 | T3: NO
A4: Arena of Glory | B4: 1 | C4: Land | D4: 0 | E4: NO | F4: 0 | G4: 0 | H4: 0 | I4: 0 | J4: 1 | K4: 0 | L4: 0 | M4: 0 | N4: 8 | O4: B | P4: KEEP | R4: Strong support card for the deck's overall plan. | S4: https://scryfall.com/search?q=%21%22Arena%20of%20Glory%22 | T4: YES
A5: Barbflare Gremlin | B5: 1 | C5: Creature — Gremlin | D5: 4 | E5: NO | F5: 0 | G5: 0 | H5: 0 | I5: 0 | J5: 0 | K5: 0 | L5: 0 | M5: 0 | N5: 6 | O5: D | P5: CUT | Q5: At 4 MV it gives opponents extra mana while trying to hurt their lands; too expensive and symmetrical for the tempo goal. | R5: At 4 MV it gives opponents extra mana while trying to hurt their lands; too expensive and symmetrical for the tempo goal. | S5: https://scryfall.com/search?q=%21%22Barbflare%20Gremlin%22 | T5: NO
A6: Basilisk Collar | B6: 1 | C6: Artifact — Equipment | D6: 1 | E6: NO | F6: 0 | G6: 0 | H6: 0 | I6: 0 | J6: 1 | K6: 0 | L6: 0 | M6: 0 | N6: 7 | O6: C | P6: CUT | Q6: Good card, but Shadowspear does the Voltron job better here by adding trample while retaining lifelink. | R6: Good card, but Shadowspear does the Voltron job better here by adding trample while retaining lifelink. | S6: https://scryfall.com/search?q=%21%22Basilisk%20Collar%22 | T6: NO
A7: Blasphemous Act | B7: 1 | C7: Sorcery | D7: 9 | E7: NO | F7: 0 | G7: 0 | H7: 2 | I7: 0 | J7: 0 | K7: 0 | L7: 0 | M7: 0 | N7: 8.5 | O7: A | P7: KEEP | R7: Strong support card for the deck's overall plan. | S7: https://scryfall.com/search?q=%21%22Blasphemous%20Act%22 | T7: NO
A8: Blasphemous Edict | B8: 1 | C8: Sorcery | D8: 5 | E8: NO | F8: 0 | G8: 0 | H8: 2 | I8: 0 | J8: 0 | K8: 0 | L8: 0 | M8: 0 | N8: 5.5 | O8: D | P8: CUT | Q8: Symmetrical sacrifice undermines the goal of ending the wipe with your creatures intact. | R8: Symmetrical sacrifice undermines the goal of ending the wipe with your creatures intact. | S8: https://scryfall.com/search?q=%21%22Blasphemous%20Edict%22 | T8: NO
A9: Blazemire Verge | B9: 1 | C9: Land | D9: 0 | E9: NO | F9: 0 | G9: 0 | H9: 0 | I9: 0 | J9: 0 | K9: 0 | L9: 0 | M9: 0 | N9: 8 | O9: B | P9: KEEP | R9: Strong support card for the deck's overall plan. | S9: https://scryfall.com/search?q=%21%22Blazemire%20Verge%22 | T9: YES
A10: Bloodchief Ascension | B10: 1 | C10: Enchantment | D10: 1 | E10: NO | F10: 0 | G10: 0 | H10: 0 | I10: 0 | J10: 1 | K10: 1 | L10: 0 | M10: 0 | N10: 9.2 | O10: A | P10: KEEP | R10: Excellent low-cost engine; becomes a kill piece with Mindcrank and naturally rides on the deck's life-loss plan. | S10: https://scryfall.com/search?q=%21%22Bloodchief%20Ascension%22 | T10: NO
A11: Bloodletter of Aclazotz | B11: 1 | C11: Creature — Demon | D11: 4 | E11: YES | F11: 0 | G11: 0 | H11: 0 | I11: 0 | J11: 0 | K11: 2 | L11: 0 | M11: 2 | N11: 8.5 | O11: A | P11: KEEP | R11: Strong support card for the deck's overall plan. | S11: https://scryfall.com/search?q=%21%22Bloodletter%20of%20Aclazotz%22 | T11: NO
A12: Bolt Bend | B12: 1 | C12: Instant | D12: 4 | E12: NO | F12: 0 | G12: 0 | H12: 0 | I12: 2 | J12: 0 | K12: 0 | L12: 0 | M12: 0 | N12: 9.2 | O12: A | P12: KEEP | R12: Strong support card for the deck's overall plan. | S12: https://scryfall.com/search?q=%21%22Bolt%20Bend%22 | T12: NO
A13: Canyon Slough | B13: 1 | C13: Land — Swamp Mountain | D13: 0 | E13: NO | F13: 0 | G13: 0 | H13: 0 | I13: 0 | J13: 0 | K13: 0 | L13: 0 | M13: 0 | N13: 7.5 | O13: B | P13: KEEP | R13: Strong support card for the deck's overall plan. | S13: https://scryfall.com/search?q=%21%22Canyon%20Slough%22 | T13: YES
A14: Chaos Warp | B14: 1 | C14: Instant | D14: 3 | E14: NO | F14: 0 | G14: 0 | H14: 2 | I14: 0 | J14: 0 | K14: 0 | L14: 0 | M14: 0 | N14: 9 | O14: A | P14: KEEP | R14: Strong support card for the deck's overall plan. | S14: https://scryfall.com/search?q=%21%22Chaos%20Warp%22 | T14: NO
A15: Command Tower | B15: 1 | C15: Land | D15: 0 | E15: NO | F15: 0 | G15: 0 | H15: 0 | I15: 0 | J15: 0 | K15: 0 | L15: 0 | M15: 0 | N15: 9 | O15: A | P15: KEEP | R15: Strong support card for the deck's overall plan. | S15: https://scryfall.com/search?q=%21%22Command%20Tower%22 | T15: YES
A16: Crypt Ghast | B16: 1 | C16: Creature — Spirit | D16: 4 | E16: NO | F16: 2 | G16: 0 | H16: 0 | I16: 0 | J16: 0 | K16: 0 | L16: 0 | M16: 0 | N16: 7 | O16: C | P16: CUT | Q16: Huge ceiling, but 4 mana for a ramp creature is slower than the low-cost accelerants this build wants. | R16: Huge ceiling, but 4 mana for a ramp creature is slower than the low-cost accelerants this build wants. | S16: https://scryfall.com/search?q=%21%22Crypt%20Ghast%22 | T16: NO
A17: Demonic Counsel | B17: 1 | C17: Sorcery | D17: 2 | E17: NO | F17: 0 | G17: 0 | H17: 0 | I17: 0 | J17: 0 | K17: 0 | L17: 0 | M17: 0 | N17: 8.5 | O17: A | P17: KEEP | R17: Strong support card for the deck's overall plan. | S17: https://scryfall.com/search?q=%21%22Demonic%20Counsel%22 | T17: NO
A18: Descent into Avernus | B18: 1 | C18: Enchantment | D18: 4 | E18: NO | F18: 2 | G18: 0 | H18: 0 | I18: 0 | J18: 0 | K18: 2 | L18: 0 | M18: 0 | N18: 8 | O18: B | P18: KEEP | R18: Strong support card for the deck's overall plan. | S18: https://scryfall.com/search?q=%21%22Descent%20into%20Avernus%22 | T18: NO
A19: Dragonskull Summit | B19: 1 | C19: Land | D19: 0 | E19: NO | F19: 0 | G19: 0 | H19: 0 | I19: 0 | J19: 0 | K19: 0 | L19: 0 | M19: 0 | N19: 8 | O19: B | P19: KEEP | R19: Strong support card for the deck's overall plan. | S19: https://scryfall.com/search?q=%21%22Dragonskull%20Summit%22 | T19: YES
A20: Exotic Orchard | B20: 1 | C20: Land | D20: 0 | E20: NO | F20: 0 | G20: 0 | H20: 0 | I20: 0 | J20: 0 | K20: 0 | L20: 0 | M20: 0 | N20: 8.5 | O20: A | P20: KEEP | R20: Strong support card for the deck's overall plan. | S20: https://scryfall.com/search?q=%21%22Exotic%20Orchard%22 | T20: YES
A21: Fate Unraveler | B21: 1 | C21: Enchantment Creature — Human Shaman | D21: 4 | E21: NO | F21: 0 | G21: 0 | H21: 0 | I21: 0 | J21: 0 | K21: 2 | L21: 0 | M21: 0 | N21: 9.3 | O21: A | P21: KEEP | R21: Strong support card for the deck's overall plan. | S21: https://scryfall.com/search?q=%21%22Fate%20Unraveler%22 | T21: NO
A22: Feed the Swarm | B22: 1 | C22: Sorcery | D22: 2 | E22: NO | F22: 0 | G22: 0 | H22: 2 | I22: 0 | J22: 0 | K22: 0 | L22: 0 | M22: 0 | N22: 8.5 | O22: A | P22: KEEP | R22: Strong support card for the deck's overall plan. | S22: https://scryfall.com/search?q=%21%22Feed%20the%20Swarm%22 | T22: NO
A23: Fellwar Stone | B23: 1 | C23: Artifact | D23: 2 | E23: NO | F23: 2 | G23: 0 | H23: 0 | I23: 0 | J23: 0 | K23: 0 | L23: 0 | M23: 0 | N23: 7.5 | O23: B | P23: KEEP | R23: Strong support card for the deck's overall plan. | S23: https://scryfall.com/search?q=%21%22Fellwar%20Stone%22 | T23: NO
A24: Foreboding Ruins | B24: 1 | C24: Land | D24: 0 | E24: NO | F24: 0 | G24: 0 | H24: 0 | I24: 0 | J24: 0 | K24: 0 | L24: 0 | M24: 0 | N24: 7.5 | O24: B | P24: KEEP | R24: Strong support card for the deck's overall plan. | S24: https://scryfall.com/search?q=%21%22Foreboding%20Ruins%22 | T24: YES
A25: Ghoulish Impetus | B25: 1 | C25: Enchantment — Aura | D25: 3 | E25: NO | F25: 0 | G25: 0 | H25: 0 | I25: 0 | J25: 0 | K25: 0 | L25: 0 | M25: 0 | N25: 6.5 | O25: C | P25: CUT | Q25: Fun Goad piece, but it is a peripheral effect rather than core Voltron, slug, protection, or Demon tribal. | R25: Fun Goad piece, but it is a peripheral effect rather than core Voltron, slug, protection, or Demon tribal. | S25: https://scryfall.com/search?q=%21%22Ghoulish%20Impetus%22 | T25: NO
A26: Gleeful Arsonist | B26: 1 | C26: Creature — Human Wizard | D26: 3 | E26: NO | F26: 0 | G26: 0 | H26: 0 | I26: 0 | J26: 0 | K26: 2 | L26: 0 | M26: 0 | N26: 9.2 | O26: A | P26: KEEP | R26: Strong support card for the deck's overall plan. | S26: https://scryfall.com/search?q=%21%22Gleeful%20Arsonist%22 | T26: NO
A27: Gray Merchant of Asphodel | B27: 1 | C27: Creature — Zombie | D27: 5 | E27: NO | F27: 0 | G27: 0 | H27: 0 | I27: 0 | J27: 0 | K27: 0 | L27: 0 | M27: 0 | N27: 7 | O27: C | P27: CUT | Q27: Strong finisher, but neither Demon nor a core Voltron/protection piece; less necessary in this shell. | R27: Strong finisher, but neither Demon nor a core Voltron/protection piece; less necessary in this shell. | S27: https://scryfall.com/search?q=%21%22Gray%20Merchant%20of%20Asphodel%22 | T27: NO
A28: Herald of Slaanesh | B28: 1 | C28: Creature — Demon | D28: 2 | E28: YES | F28: 0 | G28: 0 | H28: 0 | I28: 0 | J28: 0 | K28: 0 | L28: 0 | M28: 2 | N28: 9.2 | O28: A | P28: KEEP | R28: Strong support card for the deck's overall plan. | S28: https://scryfall.com/search?q=%21%22Herald%20of%20Slaanesh%22 | T28: NO
A29: Imp's Mischief | B29: 1 | C29: Instant | D29: 2 | E29: NO | F29: 0 | G29: 0 | H29: 0 | I29: 2 | J29: 0 | K29: 0 | L29: 0 | M29: 0 | N29: 9.2 | O29: A | P29: KEEP | R29: Strong support card for the deck's overall plan. | S29: https://scryfall.com/search?q=%21%22Imp%27s%20Mischief%22 | T29: NO
A30: Insatiable Avarice | B30: 1 | C30: Sorcery | D30: 3 | E30: NO | F30: 0 | G30: 0 | H30: 0 | I30: 0 | J30: 0 | K30: 0 | L30: 0 | M30: 0 | N30: 6.5 | O30: C | P30: CUT | Q30: Flexible, but too mana-hungry/slow relative to direct tutors and engines. | R30: Flexible, but too mana-hungry/slow relative to direct tutors and engines. | S30: https://scryfall.com/search?q=%21%22Insatiable%20Avarice%22 | T30: NO
A31: Jeska's Will | B31: 1 | C31: Sorcery | D31: 3 | E31: NO | F31: 2 | G31: 1 | H31: 0 | I31: 0 | J31: 0 | K31: 0 | L31: 0 | M31: 0 | N31: 9.5 | O31: S | P31: KEEP | R31: Strong support card for the deck's overall plan. | S31: https://scryfall.com/search?q=%21%22Jeska%27s%20Will%22 | T31: NO
A32: Karazikar, the Eye Tyrant | B32: 1 | C32: Legendary Creature — Beholder | D32: 5 | E32: NO | F32: 0 | G32: 0 | H32: 0 | I32: 0 | J32: 0 | K32: 0 | L32: 0 | M32: 0 | N32: 7.5 | O32: B | P32: CUT | Q32: Good Goad/CA card, but the deck is better when its five-mana slots directly serve Voltron, slug, protection, or Demon tribal. | R32: Good Goad/CA card, but the deck is better when its five-mana slots directly serve Voltron, slug, protection, or Demon tribal. | S32: https://scryfall.com/search?q=%21%22Karazikar%2C%20the%20Eye%20Tyrant%22 | T32: NO
A33: Kardur, Doomscourge | B33: 1 | C33: Legendary Creature — Demon | D33: 4 | E33: YES | F33: 0 | G33: 0 | H33: 0 | I33: 0 | J33: 0 | K33: 2 | L33: 0 | M33: 2 | N33: 8.8 | O33: A | P33: KEEP | R33: Strong support card for the deck's overall plan. | S33: https://scryfall.com/search?q=%21%22Kardur%2C%20Doomscourge%22 | T33: NO
A34: Kaya's Ghostform | B34: 1 | C34: Enchantment — Aura | D34: 2 | E34: NO | F34: 0 | G34: 0 | H34: 0 | I34: 2 | J34: 0 | K34: 0 | L34: 2 | M34: 0 | N34: 8.8 | O34: A | P34: KEEP | R34: Strong support card for the deck's overall plan. | S34: https://scryfall.com/search?q=%21%22Kaya%27s%20Ghostform%22 | T34: NO
A35: Kederekt Parasite | B35: 1 | C35: Creature — Horror | D35: 1 | E35: NO | F35: 0 | G35: 1 | H35: 0 | I35: 0 | J35: 0 | K35: 2 | L35: 0 | M35: 0 | N35: 9.6 | O35: S | P35: KEEP | R35: Premium 1-drop for this commander: punishes extra draws with life loss, feeding Valgavoth every opponent turn when online. | S35: https://scryfall.com/search?q=%21%22Kederekt%20Parasite%22 | T35: NO
A36: Lightning Greaves | B36: 1 | C36: Artifact — Equipment | D36: 2 | E36: NO | F36: 0 | G36: 0 | H36: 0 | I36: 2 | J36: 1 | K36: 0 | L36: 0 | M36: 0 | N36: 9.7 | O36: S | P36: KEEP | R36: Core protection, haste, and immediate Voltron pressure; one of the safest cards in the list. | S36: https://scryfall.com/search?q=%21%22Lightning%20Greaves%22 | T36: NO
A37: Liliana's Contract | B37: 1 | C37: Enchantment | D37: 5 | E37: NO | F37: 0 | G37: 2 | H37: 0 | I37: 0 | J37: 0 | K37: 0 | L37: 0 | M37: 1 | N37: 8 | O37: B | P37: KEEP | R37: Strong support card for the deck's overall plan. | S37: https://scryfall.com/search?q=%21%22Liliana%27s%20Contract%22 | T37: NO
A38: Lord of the Void | B38: 1 | C38: Creature — Demon | D38: 7 | E38: YES | F38: 0 | G38: 0 | H38: 0 | I38: 0 | J38: 0 | K38: 0 | L38: 0 | M38: 2 | N38: 6.5 | O38: C | P38: CUT | Q38: Excellent Demon, poor fit for the deck's desired speed. | R38: Powerful Demon, but 7 mana is too slow for the desired tempo and does not advance the plan immediately. | S38: https://scryfall.com/search?q=%21%22Lord%20of%20the%20Void%22 | T38: NO
A39: Mai, Scornful Striker | B39: 1 | C39: Legendary Creature — Human Noble Ally | D39: 2 | E39: NO | F39: 0 | G39: 0 | H39: 0 | I39: 0 | J39: 0 | K39: 2 | L39: 0 | M39: 0 | N39: 8.8 | O39: A | P39: KEEP | R39: Strong support card for the deck's overall plan. | S39: https://scryfall.com/search?q=%21%22Mai%2C%20Scornful%20Striker%22 | T39: NO
A40: Malakir Rebirth | B40: 1 | C40: Instant | D40: 1 | E40: NO | F40: 0 | G40: 0 | H40: 0 | I40: 2 | J40: 1 | K40: 0 | L40: 2 | M40: 0 | N40: 9 | O40: A | P40: KEEP | R40: Strong support card for the deck's overall plan. | S40: https://scryfall.com/search?q=%21%22Malakir%20Rebirth%22 | T40: NO
...

Sheet 03_Tier List
A1: Tier | B1: Card | C1: Score | D1: MV | E1: Demon? | F1: Primary Role | G1: Verdict | H1: Why
A2: S | B2: Valgavoth, Harrower of Souls | C2: 10 | D2: 4 | E2: YES | F2: Slug, Voltron, Prot | G2: LOCK | H2: Primary engine and Voltron threat. Each opponent's first life loss on their turn becomes a card plus a permanent +1/+1 counter.
A3: S | B3: Lightning Greaves | C3: 9.7 | D3: 2 | E3: NO | F3: Prot | G3: KEEP | H3: Core protection, haste, and immediate Voltron pressure; one of the safest cards in the list.
A4: S | B4: Sol Ring | C4: 9.7 | D4: 1 | E4: NO | F4: Ramp | G4: KEEP | H4: Support card; keep while testing this exact build.
A5: S | B5: Kederekt Parasite | C5: 9.6 | D5: 1 | E5: NO | F5: Slug | G5: KEEP | H5: Premium 1-drop for this commander: punishes extra draws with life loss, feeding Valgavoth every opponent turn when online.
A6: S | B6: Razorkin Needlehead | C6: 9.6 | D6: 3 | E6: NO | F6: Slug | G6: KEEP | H6: Very efficient life-loss trigger plus incremental pressure; one of the best low-curve cards for the commander.
A7: S | B7: Roiling Vortex | C7: 9.6 | D7: 2 | E7: NO | F7: Slug | G7: KEEP | H7: Cheap persistent pain engine that also punishes free spells; directly advances the commander plan.
A8: S | B8: Jeska's Will | C8: 9.5 | D8: 3 | E8: NO | F8: Ramp | G8: KEEP | H8: Support card; keep while testing this exact build.
A9: S | B9: Unholy Annex // Ritual Chamber | C9: 9.5 | D9: 3 | E9: NO | F9: Slug | G9: KEEP | H9: Excellent intersection of Demon tribal and Group Slug: draw every end step, drain opponents if a Demon is present, and later makes a 6/6 Demon.
A10: A | B10: Sulfuric Vortex | C10: 9.4 | D10: 3 | E10: NO | F10: Slug | G10: KEEP | H10: Support card; keep while testing this exact build.
A11: A | B11: Fate Unraveler | C11: 9.3 | D11: 4 | E11: NO | F11: Slug | G11: KEEP | H11: Support card; keep while testing this exact build.
A12: A | B12: Underworld Dreams | C12: 9.3 | D12: 3 | E12: NO | F12: Slug | G12: KEEP | H12: Support card; keep while testing this exact build.
A13: A | B13: Bloodchief Ascension | C13: 9.2 | D13: 1 | E13: NO | G13: KEEP | H13: Excellent low-cost engine; becomes a kill piece with Mindcrank and naturally rides on the deck's life-loss plan.
A14: A | B14: Bolt Bend | C14: 9.2 | D14: 4 | E14: NO | F14: Prot | G14: KEEP | H14: Support card; keep while testing this exact build.
A15: A | B15: Gleeful Arsonist | C15: 9.2 | D15: 3 | E15: NO | F15: Slug | G15: KEEP | H15: Support card; keep while testing this exact build.
A16: A | B16: Herald of Slaanesh | C16: 9.2 | D16: 2 | E16: YES | F16: Demon | G16: KEEP | H16: Support card; keep while testing this exact build.
A17: A | B17: Imp's Mischief | C17: 9.2 | D17: 2 | E17: NO | F17: Prot | G17: KEEP | H17: Support card; keep while testing this exact build.
A18: A | B18: Manabarbs | C18: 9.2 | D18: 4 | E18: NO | F18: Slug | G18: KEEP | H18: Support card; keep while testing this exact build.
A19: A | B19: Mandate of Abaddon | C19: 9.2 | D19: 4 | E19: NO | F19: Removal | G19: KEEP | H19: One of the best sweepers here because Valgavoth's growing power can leave the commander alive while shrinking opposing boards.
A20: A | B20: Ob Nixilis, Captive Kingpin | C20: 9.2 | D20: 4 | E20: NO | F20: Slug | G20: KEEP | H20: Support card; keep while testing this exact build.
A21: A | B21: Rakdos Charm | C21: 9.2 | D21: 2 | E21: NO | F21: Removal | G21: KEEP | H21: Support card; keep while testing this exact build.
A22: A | B22: Rampaging Ferocidon | C22: 9.2 | D22: 3 | E22: NO | F22: Slug | G22: KEEP | H22: Support card; keep while testing this exact build.
A23: A | B23: Mogis, God of Slaughter | C23: 9.1 | D23: 4 | E23: NO | F23: Slug | G23: KEEP | H23: Support card; keep while testing this exact build.
A24: A | B24: Rakdos, Lord of Riots | C24: 9.1 | D24: 4 | E24: YES | F24: Demon | G24: KEEP | H24: Support card; keep while testing this exact build.
A25: A | B25: Scrawling Crawler | C25: 9.1 | D25: 3 | E25: NO | F25: Slug | G25: KEEP | H25: Support card; keep while testing this exact build.
A26: A | B26: Chaos Warp | C26: 9 | D26: 3 | E26: NO | F26: Removal | G26: KEEP | H26: Support card; keep while testing this exact build.
A27: A | B27: Command Tower | C27: 9 | D27: 0 | E27: NO | G27: KEEP | H27: Support card; keep while testing this exact build.
A28: A | B28: Malakir Rebirth | C28: 9 | D28: 1 | E28: NO | F28: Prot, Recursion | G28: KEEP | H28: Support card; keep while testing this exact build.
A29: A | B29: The Lord of Pain | C29: 9 | D29: 6 | E29: NO | F29: Slug | G29: KEEP | H29: Support card; keep while testing this exact build.
A30: A | B30: Kardur, Doomscourge | C30: 8.8 | D30: 4 | E30: YES | F30: Slug, Demon | G30: KEEP | H30: Support card; keep while testing this exact build.
A31: A | B31: Kaya's Ghostform | C31: 8.8 | D31: 2 | E31: NO | F31: Prot, Recursion | G31: KEEP | H31: Support card; keep while testing this exact build.
A32: A | B32: Mai, Scornful Striker | C32: 8.8 | D32: 2 | E32: NO | F32: Slug | G32: KEEP | H32: Support card; keep while testing this exact build.
A33: A | B33: Mindcrank | C33: 8.8 | D33: 2 | E33: NO | G33: KEEP | H33: Support card; keep while testing this exact build.
A34: A | B34: Spiteful Visions | C34: 8.8 | D34: 4 | E34: NO | F34: Slug | G34: KEEP | H34: Support card; keep while testing this exact build.
A35: A | B35: Untimely Malfunction | C35: 8.7 | D35: 2 | E35: NO | F35: Removal | G35: KEEP | H35: Support card; keep while testing this exact build.
A36: A | B36: War Room | C36: 8.7 | D36: 0 | E36: NO | G36: KEEP | H36: Support card; keep while testing this exact build.
A37: A | B37: Withering Torment | C37: 8.7 | D37: 3 | E37: NO | F37: Removal | G37: KEEP | H37: Support card; keep while testing this exact build.
A38: A | B38: Blasphemous Act | C38: 8.5 | D38: 9 | E38: NO | F38: Removal | G38: KEEP | H38: Support card; keep while testing this exact build.
A39: A | B39: Bloodletter of Aclazotz | C39: 8.5 | D39: 4 | E39: YES | F39: Slug, Demon | G39: KEEP | H39: Support card; keep while testing this exact build.
A40: A | B40: Demonic Counsel | C40: 8.5 | D40: 2 | E40: NO | G40: KEEP | H40: Support card; keep while testing this exact build.
...

Sheet 04_Analysis
A1: 04 — ANALYSIS | CURRENT → TARGET
A3: Dimension | B3: Current | C3: Target | D3: Diagnosis
A4: Deck count | B4: 99 | C4: 100 | D4: One slot missing from the supplied list.
A5: Lands | B5: 33 | C5: 35 | D5: Do not reduce land count; add quality lands while preserving speed.
A6: Demon cards | B6: 9 | C6: 10 | D6: Subtheme is real but not a rigid tribal requirement; support cards may be non-Demons.
A7: Avg MV (nonland approx.) | B7: =3.265 -> 3.265 | C7: 3.55 | D7: Current top end is too concentrated; target is lower without gutting power.
A8: Protection / recursion | C8: High | D8: Prioritize free/cheap redirection plus counter preservation.
A9: Board control | C9: Asymmetric | D9: Favor Mandate of Abaddon / Chandra's Ignition / flexible removal over symmetric wipes.
A10: Win axis | C10: Multi-axis | D10: Primary: 21 commander damage. Secondary: slug/drain and Bloodchief Ascension + Mindcrank.
A12: Package | B12: Current count | D12: MV | E12: Cards
A13: Ramp | B13: =COUNTIF('02_Card Matrix'!F2:F84,2) -> 8 | D13: 1 | E13: 8
A14: Draw | B14: =COUNTIF('02_Card Matrix'!G2:G84,2) -> 1 | D14: 2 | E14: 18
A15: Removal | B15: =COUNTIF('02_Card Matrix'!H2:H84,2) -> 11 | D15: 3 | E15: 14
A16: Protection | B16: =COUNTIF('02_Card Matrix'!I2:I84,2) -> 9 | D16: 4 | E16: 16
A17: Voltron | B17: =COUNTIF('02_Card Matrix'!J2:J84,2) -> 1 | D17: 5 | E17: 6
A18: Group Slug | B18: =COUNTIF('02_Card Matrix'!K2:K84,2) -> 21 | D18: 6 | E18: 3
A19: Recursion | B19: =COUNTIF('02_Card Matrix'!L2:L84,2) -> 3 | D19: 7 | E19: 1
A20: Demon Tribal | B20: =COUNTIF('02_Card Matrix'!M2:M84,2) -> 10

Sheet 05_Control Panel
A1: 05 — CONTROL PANEL | WHAT THE DECK IS TRYING TO DO
A3: LOCKED CORE | B3: Role | C3: Why | D3: Cut? | F3: FIRST CUTS | G3: Priority | H3: Reason
A4: Valgavoth, Harrower of Souls | B4: Core engine | C4: Primary engine and Voltron threat. Each opponent's first life loss on their turn becomes a card plus a permanent +1/+1 counter. | D4: NO — baseline unless meta proves otherwise | F4: Barbflare Gremlin | G4: High | H4: At 4 mana it gives opponents extra mana while trying to hurt their lands; too expensive and symmetrical for the tempo goal.
A5: Bloodchief Ascension | B5: Core engine | C5: Excellent low-cost engine; becomes a kill piece with Mindcrank and naturally rides on the deck's life-loss plan. | D5: NO — baseline unless meta proves otherwise | F5: Basilisk Collar | G5: High | H5: Good card, but Shadowspear does the Voltron job better here by adding trample while retaining lifelink.
A6: Kederekt Parasite | B6: Core engine | C6: Premium 1-drop for this commander: punishes extra draws with life loss, feeding Valgavoth every opponent turn when online. | D6: NO — baseline unless meta proves otherwise | F6: Crypt Ghast | G6: High | H6: Huge ceiling, but 4 mana for a ramp creature is slower than the low-cost accelerants this build wants.
A7: Razorkin Needlehead | B7: Core engine | C7: Very efficient life-loss trigger plus incremental pressure; one of the best low-curve cards for the commander. | D7: NO — baseline unless meta proves otherwise | F7: Ghoulish Impetus | G7: High | H7: Fun Goad piece, but it is a peripheral effect rather than core Voltron, slug, protection, or Demon tribal.
A8: Roiling Vortex | B8: Core engine | C8: Cheap persistent pain engine that also punishes free spells; directly advances the commander plan. | D8: NO — baseline unless meta proves otherwise | F8: Insatiable Avarice | G8: High | H8: Flexible, but too mana-hungry/slow relative to direct tutors and engines.
A9: Underworld Dreams | B9: Core engine | C9: Directly supports commander growth, slug pressure or resilience. | D9: NO — baseline unless meta proves otherwise | F9: Lord of the Void | G9: High | H9: Excellent Demon, poor fit for the deck's desired speed.
A10: Mogis, God of Slaughter | B10: Core engine | C10: Directly supports commander growth, slug pressure or resilience. | D10: NO — baseline unless meta proves otherwise | F10: Nuclear Fallout | G10: High | H10: Symmetric sweep that can kill your commander and your support board; not aligned with resilience.
A11: Fate Unraveler | B11: Core engine | C11: Directly supports commander growth, slug pressure or resilience. | D11: NO — baseline unless meta proves otherwise | F11: Profane Tutor | G11: High | H11: Two-turn setup is notably slower than direct tutoring in a deck that wants to establish Valgavoth fast.
A12: Lightning Greaves | B12: Core engine | C12: Core protection, haste, and immediate Voltron pressure; one of the safest cards in the list. | D12: NO — baseline unless meta proves otherwise | F12: Gray Merchant of Asphodel | G12: High | H12: Strong finisher, but neither Demon nor a core Voltron/protection piece; less necessary in this shell.
A13: Bolt Bend | B13: Core engine | C13: Directly supports commander growth, slug pressure or resilience. | D13: NO — baseline unless meta proves otherwise | F13: Massacre Wurm | G13: High | H13: Powerful six-drop, but too far from the main plan compared with one-sided or commander-centric removal.
A14: Mandate of Abaddon | B14: Core engine | C14: One of the best sweepers here because Valgavoth's growing power can leave the commander alive while shrinking opposing boards. | D14: NO — baseline unless meta proves otherwise | F14: Vilis, Broker of Blood | G14: High | H14: Eight-mana payoff is impressive but creates a top-end bottleneck.
... A18: Rakdos Charm | B18: Core engine | C18: Directly supports commander growth, slug pressure or resilience. | D18: NO — baseline unless meta proves otherwise | F18: Spinerock Knoll | G18: High | H18: Powerful in long games, but enters tapped and is conditional; a faster untapped utility land is better here.
F19: Thought Vessel | G19: High | H19: The commander already supplies card flow; this slot is better used on mana/tempo.

Sheet 06_Watchlist
A1: Priority | B1: Card | C1: MV | D1: Why it fits | E1: Theme | F1: Risk | G1: Recommendation | H1: Source
A2: 1 | B2: Harsh Mentor | C2: 2 | D2: Cheap opponent-turn life-loss trigger from activated abilities; excellent at low curve. | E2: Slug | F2: Meta dependent | G2: HIGH PRIORITY TEST | H2: https://edhrec.com/commanders/valgavoth-harrower-of-souls/voltron
A3: 1 | B3: Solphim, Mayhem Dominus | C3: 4 | D3: Doubles noncombat damage, making the slug plan close faster; protects itself. | E3: Voltron + Slug | F3: Not a Demon | G3: HIGH PRIORITY TEST | H3: https://edhrec.com/commanders/valgavoth-harrower-of-souls/optimized/burn
A4: 1 | B4: Orcish Bowmasters | C4: 2 | D4: Punishes opponent draw and can cause opponent-turn life loss while generating board value. | E4: Slug | F4: Not a Demon | G4: HIGH PRIORITY TEST | H4: https://edhrec.com/commanders/valgavoth-harrower-of-souls
A5: 2 | B5: Commander's Plate | C5: 3 | D5: Strong Voltron power plus protection. | E5: Voltron | F5: Less direct than instant-speed protection | G5: TEST | H5: https://edhrec.com/commanders/valgavoth-harrower-of-souls/voltron
A6: 2 | B6: Hatred | C6: 5 | D6: Potential one-shot commander-damage kill. | E6: Voltron | F6: Consumes life; risky in Group Slug | G6: TEST | H6: https://scryfall.com/search?q=%21%22Hatred%22
A7: 2 | B7: Unleash Fury | C7: 3 | D7: Cheap surprise power-doubling for commander damage. | E7: Voltron | F7: One-shot / no protection | G7: TEST | H7: https://scryfall.com/search?q=%21%22Unleash%20Fury%22
A8: 2 | B8: Archfiend of Despair | C8: 8 | D8: Powerful Demon finisher that doubles life loss. | E8: Demon + Slug | F8: Too slow for main curve | G8: WATCH | H8: https://edhrec.com/commanders/valgavoth-harrower-of-souls/demons
A9: 3 | B9: Bedevil | C9: 3 | D9: Efficient catch-all removal if a future meta demands more unconditional interaction. | E9: Removal | F9: Three mana | G9: WATCH | H9: https://scryfall.com/search?q=%21%22Bedevil%22

Sheet 07_Upgrade Matrix
A1: OUT | B1: IN | C1: Delta | D1: Reason | E1: Priority | F1: Source
A2: Barbflare Gremlin | B2: Ankh of Mishra | C2: Speed / trigger + | D2: Two mana and every land entry costs 2 life; cleaner opponent-turn trigger than the 4-MV Gremlin. | E2: 1 | F2: https://edhrec.com/commanders/valgavoth-harrower-of-souls
A3: Basilisk Collar | B3: Shadowspear | C3: Voltron + | D3: Retains lifelink but adds trample, improving the 21-damage route. | E3: 1 | F3: https://scryfall.com/search?q=%21%22Shadowspear%22
A4: Crypt Ghast | B4: Dark Ritual | C4: Speed + | D4: Trade a 4-MV mana creature for a 1-MV burst that can enable turn-two Valgavoth. | E4: 1 | F4: https://edhrec.com/commanders/valgavoth-harrower-of-souls/optimized
A5: Ghoulish Impetus | B5: Swiftfoot Boots | C5: Resilience + | D5: A second cheap protective equipment is more consistently useful than situational Goad. | E5: 1 | F5: https://edhrec.com/commanders/valgavoth-harrower-of-souls/voltron
A6: Insatiable Avarice | B6: Demonic Tutor | C6: Speed + | D6: Direct tutor now; no waiting period for setup. | E6: 1 | F6: https://edhrec.com/commanders/valgavoth-harrower-of-souls/optimized
A7: Lord of the Void | B7: Archfiend of Depravity | C7: Curve + | D7: Keeps a Demon slot while reducing the top-end burden and repeatedly shrinking opposing boards. | E7: 1 | F7: https://edhrec.com/commanders/valgavoth-harrower-of-souls/demons
A8: Nuclear Fallout | B8: Sheoldred, the Apocalypse | C8: Resilience + | D8: Improves life total and punishes normal opponent draw steps without wiping your own board. | E8: 1 | F8: https://edhrec.com/commanders/valgavoth-harrower-of-souls
A9: Profane Tutor | B9: Deflecting Swat | C9: Protection + | D9: Zero-mana protection while the commander is out is more valuable to this exact plan than a delayed tutor. | E9: 1 | F9: https://edhrec.com/commanders/valgavoth-harrower-of-souls/voltron
A10: Gray Merchant of Asphodel | B10: The Ozolith | C10: Voltron + | D10: Preserves accumulated counters when the commander leaves, making the main win condition more resilient. | E10: 1 | F10: https://scryfall.com/search?q=%21%22The%20Ozolith%22
A11: Massacre Wurm | B11: Chandra's Ignition | C11: Asymmetric control + | D11: Uses Valgavoth's current power to sweep opposing creatures and damage opponents without damaging Valgavoth. | E11: 1 | F11: https://scryfall.com/search?q=%21%22Chandra%27s%20Ignition%22
A12: Vilis, Broker of Blood | B12: Branching Evolution | C12: Voltron + | D12: Each opponent-turn trigger can become two counters instead of adding an 8-MV draw engine. | E12: 1 | F12: https://edhrec.com/commanders/valgavoth-harrower-of-souls/plus-1-plus-1-counters
... A19: Thought Vessel | B19: Swamp (13th) | C19: +1 land / lower nonland density | D19: The commander already generates cards; a 13th Swamp improves the chance of casting Valgavoth on curve and raises the deck to 35 lands. | E19: 1 | F19: https://scryfall.com/search?q=%21%22Swamp%22

Sheet 08_V2 Deck
A1: Card | B1: Qty | C1: Status | D1: Land? | E1: Demon? | F1: MV | G1: Score | I1: Check | J1: Value
A2: Valgavoth, Harrower of Souls | B2: 1 | C2: COMMANDER | D2: NO | E2: YES | F2: 4 | G2: 10 | I2: Total cards | J2: =SUM(B2:B84) -> 100
A3: Arcane Signet | B3: 1 | C3: KEEP | D3: NO | E3: NO | F3: 2 | G3: 7.5 | I3: Lands | J3: =SUMIF(D2:D84,"YES",B2:B84) -> 35
A4: Arena of Glory | B4: 1 | C4: KEEP | D4: YES | E4: NO | F4: 0 | G4: 8 | I4: Spells | J4: =J2-J3-1 -> 64
A5: Blasphemous Act | B5: 1 | C5: KEEP | D5: NO | E5: NO | F5: 9 | G5: 8.5 | I5: Demons | J5: =SUMIF(E2:E84,"YES",B2:B84) -> 9
A6: Blazemire Verge | B6: 1 | C6: KEEP | D6: YES | E6: NO | F6: 0 | G6: 8 | I6: Avg score | J6: =SUMPRODUCT(B2:B84,G2:G84)/SUM(B2:B84) -> 8.61
A7: Bloodchief Ascension | B7: 1 | C7: KEEP | D7: NO | E7: NO | F7: 1 | G7: 9.2 | I7: Curve target | J7: 35 lands / lower curve / resilience
A8: Bloodletter of Aclazotz | B8: 1 | C8: KEEP | D8: NO | E8: YES | F8: 4 | G8: 8.5
A9: Bolt Bend | B9: 1 | C9: KEEP | D9: NO | E9: NO | F9: 4 | G9: 9.2
A10: Canyon Slough | B10: 1 | C10: KEEP | D10: YES | E10: NO | F10: 0 | G10: 7.5
A11: Chaos Warp | B11: 1 | C11: KEEP | D11: NO | E11: NO | F11: 3 | G11: 9
A12: Command Tower | B12: 1 | C12: KEEP | D12: YES | E12: NO | F12: 0 | G12: 9
A13: Demonic Counsel | B13: 1 | C13: KEEP | D13: NO | E13: NO | F13: 2 | G13: 8.5
A14: Descent into Avernus | B14: 1 | C14: KEEP | D14: NO | E14: NO | F14: 4 | G14: 8
A15: Dragonskull Summit | B15: 1 | C15: KEEP | D15: YES | E15: NO | F15: 0 | G15: 8
A16: Exotic Orchard | B16: 1 | C16: KEEP | D16: YES | E16: NO | F16: 0 | G16: 8.5
A17: Fate Unraveler | B17: 1 | C17: KEEP | D17: NO | E17: NO | F17: 4 | G17: 9.3
A18: Feed the Swarm | B18: 1 | C18: KEEP | D18: NO | E18: NO | F18: 2 | G18: 8.5
A19: Fellwar Stone | B19: 1 | C19: KEEP | D19: NO | E19: NO | F19: 2 | G19: 7.5
... A84: Castle Locthwain | B84: 1 | C84: UPGRADE | D84: YES | E84: NO | F84: 0 | G84: 8.7

Sheet 09_Sources
A1: Source | B1: URL | C1: Use | D1: Checked
A2: EDHREC — Valgavoth | B2: https://edhrec.com/commanders/valgavoth-harrower-of-souls | C2: Current adoption, tags and top cards | D2: 2026-10-06
A3: EDHREC — Valgavoth Voltron | B3: https://edhrec.com/commanders/valgavoth-harrower-of-souls/voltron | C3: Voltron-specific current data | D3: 2026-10-06
A4: EDHREC — Valgavoth +1/+1 | B4: https://edhrec.com/commanders/valgavoth-harrower-of-souls/plus-1-plus-1-counters | C4: Counter package cross-check | D4: 2026-10-06
A5: EDHREC — Valgavoth Demons | B5: https://edhrec.com/commanders/valgavoth-harrower-of-souls/demons | C5: Demon subtheme cross-check | D5: 2026-10-06
A6: EDHREC — Group Slug | B6: https://edhrec.com/commanders/valgavoth-harrower-of-souls/core/group-slug | C6: Core Group Slug card density | D6: 2026-10-06
A7: EDH.Wiki — Valgavoth | B7: https://edh.wiki/commanders/valgavoth-harrower-of-souls/ | C7: Commander mechanics/playstyle | D7: 2026-10-06
A8: Wizards — Duskmourn Release Notes | B8: https://magic.wizards.com/en/news/feature/duskmourn-house-of-horror-release-notes | C8: Official Valgavoth Oracle/rules | D8: 2026-10-06

Sheet 10_Read Me
A1: 10 — READ ME | VALGAVOTH DESIGN RULES
A3: Principle | B3: Definition
A4: Identity | B4: Rakdos Group Slug with Voltron as the PRIMARY win route and Demon Tribal as the SUBTHEME.
A5: Commander Engine | B5: The first life loss of each opponent during their own turn puts a +1/+1 counter on Valgavoth and draws a card.
A6: Primary Win | B6: Reach 21 commander damage as efficiently as possible.
A7: Secondary Wins | B7: Group Slug drains, damage multipliers, and Bloodchief Ascension + Mindcrank.
A8: Resilience | B8: Protect the commander, preserve accumulated counters, and favor effects that leave your board intact.
A9: Removal Philosophy | B9: Prefer asymmetric or commander-centric sweepers. Symmetric wipes are expensive because they reset your Voltron investment.
A10: Mana Philosophy | B10: Do NOT reduce the land count to make room. Target 35 lands in the revised list.
A11: Curve Philosophy | B11: Avoid unnecessary 6–8 MV cards. Establish Valgavoth early and spend mana on protection/pressure.
A12: Demon Subtheme | B12: Non-Demons are allowed only when they materially improve speed, life-loss triggering, protection, removal, Voltron or tribal support.
A13: Score | B13: 0–10 fit for THIS deck, not generic Commander strength.
A14: Tier | B14: S = 9.5–10; A = 8.5–9.4; B = 7.5–8.4; C = 6.5–7.4; D < 6.5.
... A16: V2 Target | B16: 35 lands + 64 spells + commander; lower curve, stronger protection, stronger counter scaling, better asymmetrical control.
